Workbook
Name avg_equity: Ratios!$C$33
Name avg_total_assets: Ratios!$C$34
Name avg_total_capitalization: Ratios!$C$35
Name cost_capital: Ratios!$C$7
Name currentYear_after_tax_operating_income: Ratios!$C$19
Name currentYear_assets_current: Ratios!$C$23
Name currentYear_assets_total: Ratios!$C$28
Name currentYear_cash_marketable_securities: Ratios!$C$22
Name currentYear_cost_goods_sold_daily: Ratios!$C$25
Name currentYear_daily_sales_average: Ratios!$C$20
Name currentYear_debt_long_term: Ratios!$C$26
Name currentYear_equity: Ratios!$C$21
Name currentYear_liabilities_current: Ratios!$C$24
Name currentYear_liabilities_total: Ratios!$C$30
Name currentYear_total_capitalization: Ratios!$C$29
Name currentYear_working_capital_net: Ratios!$C$27
Name debt_long_term_equity: Ratios!$C$36
Name market_capitalization: Ratios!$C$9
Name share_price: Ratios!$C$5
Name shares_outstanding: Ratios!$C$6
Name startYear_equity: Ratios!$C$12
Name startYear_inventory: Ratios!$C$13
Name startYear_receivables: Ratios!$C$14
Name startYear_total_assets: Ratios!$C$15
Name startYear_total_capitalization: Ratios!$C$16
Name tax_rate: Ratios!$C$8
Name yearCurrent: Ratios!$C$3
Name yearStart: Ratios!$C$4

Sheet Balance Sheet
B1: Balance Sheet — Caterpillar Inc. (CAT)
B2: ASSETS | C2: FY2024 (Dec 31, 2024) | D2: FY2023 (Dec 31, 2023) | F2: LIABILITIES & EQUITY | G2: FY2024 (Dec 31, 2024) | H2: FY2023 (Dec 31, 2023)
B3: (All figures in $millions) | F3: (All figures in $millions)
B4: Current Assets | F4: Current Liabilities
B5: Cash and marketable securities | C5: 5728 | D5: 6061 | F5: Debt due for repayment | G5: 9263 | H5: 8574
B6: Receivables | C6: 8142 | D6: 8014 | F6: Accounts payable | G6: 3748 | H6: 3892
B7: Inventories | C7: 12476 | D7: 13693 | F7: Other current liabilities | G7: 7064 | H7: 7213
B8: Other current assets | C8: 1855 | D8: 1720 | F8: Total current liabilities | G8: =SUM(G5:G7) -> 20075 | H8: =SUM(H5:H7) -> 19679
B9: Total current assets | C9: =SUM(C5:C8) -> 28201 | D9: =SUM(D5:D8) -> 29488
F10: Long-term debt | G10: 25046 | H10: 25107
B11: Fixed Assets | F11: Other long-term liabilities | G11: 8726 | H11: 8684
B12: Property, plant, and equipment | C12: 15818 | D12: 15262
B13: Less accumulated depreciation | C13: 9651 | D13: 9183 | F13: Total Liabilities | G13: =G8+G10+G11 -> 53847 | H13: =H8+H10+H11 -> 53470
B14: Net tangible fixed assets | C14: =C12-C13 -> 6167 | D14: =D12-D13 -> 6079
F15: Shareholders' Equity
B16: Other Assets | F16: Common stock and paid-in capital | G16: 2118 | H16: 2118
B17: Intangible assets (goodwill) | C17: 7293 | D17: 7301 | F17: Retained earnings | G17: 30063 | H17: 26844
B18: Other assets | C18: =G20-C9-C14-C17 -> 44367 | D18: =H20-D9-D14-D17 -> 39564 | F18: Total shareholders' equity | G18: =G16+G17 -> 32181 | H18: =H16+H17 -> 28962
B20: Total Assets | C20: =C9+C14+C17+C18 -> 86028 | D20: =D9+D14+D17+D18 -> 82432 | F20: Total Liabilities + Equity | G20: =G13+G18 -> 86028 | H20: =H13+H18 -> 82432
B21: Balance Check (TA − TL&E) | C21: =C20-G20 -> 0
B22: Source: Caterpillar 10-K FY2024, SEC EDGAR

Sheet Income Statement
B1: Income Statement — Caterpillar Inc. (CAT)
B2: Line Item | C2: FY2024 (Dec 31, 2024) | D2: % of Sales
B3: (All figures in $millions)
B4: Net sales | C4: 64809 | D4: =IF(C$4=0,0,C4/C$4) -> 1
B5: less Cost of goods sold | C5: 43244 | D5: =IF(C$4=0,0,C5/C$4) -> 0.667253
B6: less Selling, general & administrative | C6: =C4-C5 -> 21565 | D6: =IF(C$4=0,0,C6/C$4) -> 0.332747
B7: less Depreciation | C7: 1413 | D7: 0.021802527
B8: Earnings before interest & taxes (EBIT) | C8: 14187 | D8: =IF(C$4=0,0,C8/C$4) -> 0.21890478
D9: =IF(C$4=0,0,C9/C$4) -> 0
B10: plus Other income | C10: 2116 | D10: =IF(C$4=0,0,C10/C$4) -> 0.032649786
B11: less Interest expense | C11: 1713 | D11: 0.026431514
B12: Taxable income | C12: =C6-C8-C9-C10 -> 5262 | D12: =IF(C$4=0,0,C12/C$4) -> 0.081192427
D13: =IF(C$4=0,0,C13/C$4) -> 0
B14: less Taxes | C14: 2944 | D14: 0.04542579
B15: Net income | C15: =C12-C13 -> 5262 | D15: =IF(C$4=0,0,C15/C$4) -> 0.081192427
D16: =IF(C$4=0,0,C16/C$4) -> 0
B17: Allocation of Net Income | C17: =C15-C16 -> 5262 | D17: =IF(C$4=0,0,C17/C$4) -> 0.081192427
B18: Dividends | C18: 2736 | D18: =IF(C$4=0,0,C18/C$4) -> 0.042216359
B19: Addition to retained earnings | C19: =C17-C18 -> 2526 | D19: =IF(C$4=0,0,C19/C$4) -> 0.038976068
B21: Source: Caterpillar 10-K FY2024, SEC EDGAR

Sheet Cash Flow Statement
B1: Cash Flow Statement — Caterpillar Inc. (CAT)
B2: Line Item | C2: FY2024 (Dec 31, 2024) | D2: Source / Notes
B3: (All figures in $millions)
B4: Operations:
B5: Net income | C5: 11646 | D5: [Income Statement]
B6: plus Depreciation | C6: 1413 | D6: [Income Statement]
B7: plus Changes in working capital items
B8: Decrease (increase) in accounts receivable | C8: -128 | D8: [Balance Sheet]
B9: Decrease (increase) in inventories | C9: 1217 | D9: [Balance Sheet]
B10: Decrease (increase) in other current assets | C10: -135 | D10: [Balance Sheet]
B11: Increase (decrease) in accounts payable | C11: -144 | D11: [Balance Sheet]
B12: Increase (decrease) in other current liabilities | C12: -149 | D12: [Balance Sheet]
B13: Total change in working capital | C13: =SUM(C8:C12) -> 661
B14: Cash provided by operations | C14: =C5+C6+C13 -> 13720
B16: Investments:
B17: Capital expenditures | C17: -1702
B18: plus Sales (acquisitions) of long-term assets | C18: 298
B19: plus Other investing activities | C19: -782
B20: Cash provided by (used for) investments | C20: =SUM(C17:C19) -> -2186
B22: Financing activities:
B23: Increase (decrease) in short-term debt | C23: 689
B24: plus Increase (decrease) in long-term debt | C24: -61
B25: plus Dividends | C25: -2736
B26: plus Issues (repurchases) of stock | C26: -7839
B27: plus Other | C27: -327
B28: Cash provided by (used for) financing | C28: =SUM(C23:C27) -> -10274
B30: Net increase (decrease) in cash | C30: =C14+C20+C28 -> 1260
B32: Source: Caterpillar 10-K FY2024, SEC EDGAR

Sheet Ratios
B1: Ratios — Caterpillar Inc. (CAT)
B2: Metric | C2: Input | D2: Named Range Formula | E2: Named Range
B3: Current year | C3: 2024 | E3: yearCurrent
B4: Start of year | C4: 2023 | D4: yearCurrent - 1 | E4: yearStart
B5: Share price | C5: 349.58 | E5: share_price
B6: Shares outstanding (M) | C6: 492 | E6: shares_outstanding
B7: Cost of capital | C7: 0.079 | E7: cost_capital
B8: Tax rate | C8: 0.214 | E8: tax_rate
B9: Market capitalization | C9: =C5*C6 -> 171993.36 | D9: share_price × shares_outstanding | E9: market_capitalization
B11: ─── Start of Year (Prior Year Balance Sheet) ───
B12: Equity (start of year) | C12: ='Balance Sheet'!H18 -> 28962 | D12: BAL_equity_shareholders_2023 | E12: startYear_equity
B13: Inventories (start of year) | C13: ='Balance Sheet'!D7 -> 13693 | D13: BAL_inventories_2023 | E13: startYear_inventory
B14: Receivables (start of year) | C14: ='Balance Sheet'!D6 -> 8014 | D14: BAL_receivables_2023 | E14: startYear_receivables
B15: Total assets (start of year) | C15: ='Balance Sheet'!D20 -> 82432 | D15: BAL_assets_total_2023 | E15: startYear_total_assets
B16: Total capitalization (start of year) | C16: ='Balance Sheet'!H10+'Balance Sheet'!H18 -> 54069 | D16: BAL_debt_long_term_2023 + BAL_equity_shareholders_2023 | E16: startYear_total_capitalization
B18: ─── Current Year (Derived) ───
B19: After-tax operating income | C19: ='Income Statement'!C17+(1-C8)*'Income Statement'!C13 -> 5262 | D19: INC_net + (1−tax_rate) × INC_interest_expense | E19: currentYear_after_tax_operating_income
B20: Average daily sales | C20: ='Income Statement'!C4/365 -> 177.5589 | D20: INC_sales / 365 | E20: currentYear_daily_sales_average
B21: Book value of equity | C21: ='Balance Sheet'!G18 -> 32181 | D21: BAL_equity_shareholders_2024 | E21: currentYear_equity
B22: Cash + Mktable securities | C22: ='Balance Sheet'!C5 -> 5728 | D22: BAL_cash_marketable_securities_2024 | E22: currentYear_cash_marketable_securities
B23: Current assets | C23: ='Balance Sheet'!C9 -> 28201 | D23: BAL_assets_current_2024 | E23: currentYear_assets_current
B24: Current liabilities | C24: ='Balance Sheet'!G8 -> 20075 | D24: BAL_liabilities_current_2024 | E24: currentYear_liabilities_current
B25: Daily COGS | C25: ='Income Statement'!C5/365 -> 118.47671 | D25: INC_cost_goods_sold / 365 | E25: currentYear_cost_goods_sold_daily
B26: Long-term debt | C26: ='Balance Sheet'!G10 -> 25046 | D26: BAL_debt_long_term_2024 | E26: currentYear_debt_long_term
B27: Net working capital | C27: ='Balance Sheet'!C9-'Balance Sheet'!G8 -> 8126 | D27: BAL_assets_current_2024 − BAL_liabilities_current_2024 | E27: currentYear_working_capital_net
B28: Total assets | C28: ='Balance Sheet'!C20 -> 86028 | D28: BAL_assets_total_2024 | E28: currentYear_assets_total
B29: Total capitalization | C29: ='Balance Sheet'!G10+'Balance Sheet'!G18 -> 57227 | D29: BAL_debt_long_term_2024 + BAL_equity_shareholders_2024 | E29: currentYear_total_capitalization
B30: Total liabilities | C30: ='Balance Sheet'!G13 -> 53847 | D30: BAL_liabilities_total_2024 | E30: currentYear_liabilities_total
B32: ─── Mixed Year (Averages) ───
B33: Average equity | C33: =AVERAGE(C12,C21) -> 30571.5 | D33: AVERAGE(startYear_equity, currentYear_equity) | E33: avg_equity
B34: Average total assets | C34: =AVERAGE(C15,C28) -> 84230 | D34: AVERAGE(startYear_total_assets, currentYear_assets_total) | E34: avg_total_assets
B35: Average total capitalization | C35: =AVERAGE(C16,C29) -> 55648 | D35: AVERAGE(startYear_total_capitalization, currentYear_total_capitalization) | E35: avg_total_capitalization
B36: Long-term debt + Equity | C36: =C26+C21 -> 57227 | D36: currentYear_debt_long_term + currentYear_equity | E36: debt_long_term_equity
B39: Ratio | C39: Output ← Students Complete | D39: Named Range Formula (reference) | E39: Named Range
B40: Performance
B41: Market value added (MVA) | C41: =market_capitalization-currentYear_equity -> 139812.36 | D41: market_capitalization − currentYear_equity
B42: Market-to-book ratio | C42: =market_capitalization/currentYear_equity -> 5.3445623 | D42: market_capitalization / currentYear_equity
B43: Economic value added (EVA) | C43: =currentYear_after_tax_operating_income-( cost_capital*startYear_total_capitalization) -> 990.549 | D43: currentYear_after_tax_operating_income − (cost_capital × startYear_total_capitalization)
B45: Profitability
B46: Return on assets (ROA) | C46: =currentYear_after_tax_operating_income/startYear_total_assets -> 0.063834433 | D46: currentYear_after_tax_operating_income / startYear_total_assets
...

Sheet Notes
B1: Notes & Assumptions — Caterpillar Inc. (CAT)
B3: Company: | C3: Caterpillar Inc.
B4: Ticker: | C4: CAT
B5: Industry: | C5: Industrials – Heavy Machinery & Equipment
B6: Fiscal Year (current): | C6: FY2024 (Dec 31, 2024)
B7: Fiscal Year (prior): | C7: FY2023 (Dec 31, 2023)
B8: Data Source: | C8: Caterpillar 10-K FY2024, SEC EDGAR
B9: Units: | C9: All figures in millions of US dollars unless otherwise noted.
B10: Tax Rate: | C10: 21.4% — use as analyst assumption (adjust to effective rate if preferred)
B11: Cost of Capital: | C11: 7.9% — estimated WACC; students may refine using CAPM + class methodology
B12: Share Price: | C12: $349.58 — end-of-fiscal-year closing price
B13: Shares Outstanding: | C13: 492M shares
B15: BUS-314 Project Use: | C15: This workbook provides real financial statement data for the Accounting & Performance Ratios project.
... B20: AI Usage: | C20: [Document any AI tools used and how they were applied — required per course AI guidelines]
